Workbook
Name BRANCHOFSERVICE: Data_Income!$C$813:$C$828
Name FAMILYSIZE: #REF!
Name FREQUENCY: Data_Income!$C$48:$C$57
Name M_DOCTYPES: Data_Income!$C$106:$C$115
Name M_PAYDOCS: Data_Income!$B$48:$B$57
Name M_YEARS: Data_Income!$C$27:$C$32
Name RESIDUALACTUAL: 'Res Inc Data'!$B$46
Name RESIDUALDIFF: 'Res Inc Data'!$B$48
Name RESIDUALREQUIRED: 'Res Inc Data'!$B$45
Name STATESELECTED: 'Res Inc Data'!$B$41
Name STATESLIST: 'Res Inc Data'!$D$67:$D$118
Name WVOEHEADINGS: Data_Income!$C$94:$C$102
Name YEARN: Data_Income!$B$8
Name YEARP1: Data_Income!$B$10
Name YEARP2: Data_Income!$B$11
Name YRCB: Data_Income!$B$13
Name YRP1B: Data_Income!$B$14
Name YRP1E: Data_Income!$B$15
Name YRP2B: Data_Income!$B$16
Name YRP2E: Data_Income!$B$17

Sheet Rental income
A1: Rental Income Worksheet
A2: Individual Rental Income from Investment Property(s): Monthly Qualifying Rental Income (or Loss)
D3: Enter | E3: Investment Property Address | F3: Investment Property Address | G3: Investment Property Address | H3: Investment Property Address | I3: Investment Property Address | J3: Investment Property Address | K3: Investment Property Address | L3: Investment Property Address | M3: Investment Property Address | N3: Investment Property Address
A6: Step 1. When using Schedule E, determine the number of months the property was in service by dividing the Fair Rental Days by 30.
A7: If Fair Rental Days are not reported, the property is considered to be in service for 12 months unless there is evidence of a shorter term of service.
A8: Step 1. Result: Enter the number of months the property was in service: | D8: Result
A9: Step 2. Calculate monthly qualifying rental income (loss) using Step 2A: Schedule E OR Step 2B: Lease Agreement or Fannie Mae Form 1007 or Form 1025.
A10: Step 2A. Schedule E - Part I For each property complete ONLY 2A or 2B
A11: A1 | B11: Enter total rents received. | D11: Enter
A12: A2 | B12: Enter total expenses. | D12: Subtract
A13: A3 | B13: Enter insurance expense. | D13: Add
A14: A4 | B14: Enter mortgage interest paid. | D14: Add
A15: A5 | B15: Enter tax expense. | D15: Add
A16: A6 | B16: Enter homeowners’ association dues. | D16: Add
B17: This expense must be specifically identified on Schedule E in order to add it back.
A18: A7 | B18: Enter depreciation expense or depletion. | D18: Add
A19: A8 | B19: Enter any one-time extraordinary expense (e.g., casualty loss). There must be evidence of the nature of the one-time extraordinary expense. | D19: Add
B20: Equals adjusted rental income. | D20: Total | E20: =SUM(E11,E13:E19)-E12 -> 0 | F20: =SUM(F11,F13:F19)-F12 -> 0 | G20: =SUM(G11,G13:G19)-G12 -> 0 | H20: =SUM(H11,H13:H19)-H12 -> 0 | I20: =SUM(I11,I13:I19)-I12 -> 0 | J20: =SUM(J11,J13:J19)-J12 -> 0 | K20: =SUM(K11,K13:K19)-K12 -> 0 | L20: =SUM(L11,L13:L19)-L12 -> 0 | ... N20: =SUM(N11,N13:N19)-N12 -> 0
A21: A9 | B21: Enter the number of months the property was in service (Step 1 Result). | D21: Divide | E21: =E8 -> 0 | F21: =F8 -> 0 | G21: =G8 -> 0 | H21: =H8 -> 0 | I21: =I8 -> 0 | J21: =J8 -> 0 | K21: =K8 -> 0 | L21: =L8 -> 0 | ... N21: =N8 -> 0
B22: Equals adjusted monthly rental income | D22: Total | E22: =IF(E21=0,0,E20/E21) -> 0 | F22: =IF(F21=0,0,F20/F21) -> 0 | G22: =IF(G21=0,0,G20/G21) -> 0 | H22: =IF(H21=0,0,H20/H21) -> 0 | I22: =IF(I21=0,0,I20/I21) -> 0 | J22: =IF(J21=0,0,J20/J21) -> 0 | K22: =IF(K21=0,0,K20/K21) -> 0 | L22: =IF(L21=0,0,L20/L21) -> 0 | ... N22: =IF(N21=0,0,N20/N21) -> 0
A23: A10 | B23: Enter proposed PITIA (for subject property) or | D23: Subtract
B24: existing PITIA (for non-subject property).
A25: Step 2A. Result: Monthly qualifying rental income (or loss): | D25: Result | E25: =E22-E23 -> 0 | F25: =F22-F23 -> 0 | G25: =G22-G23 -> 0 | H25: =H22-H23 -> 0 | I25: =I22-I23 -> 0 | J25: =J22-J23 -> 0 | K25: =K22-K23 -> 0 | L25: =L22-L23 -> 0 | ... N25: =N22-N23 -> 0
A26: Step 2B. Lease Agreement OR Fannie Mae Form 1007 or Form 1025 For each property complete ONLY 2A or 2B
A27: This method is used when the transaction is a purchase, the property was acquired subsequent to the most recent tax filing, or the lender has justification for using a lease agreement.
A28: B1 | B28: Enter the gross monthly rent (from the lease agreement) or | D28: Enter
B29: market rent (reported on Form 1007 or Form 1025).
B30: For multi-unit properties, combine gross rent from all rental units.
A31: B2 | B31: The remaining 25% accounts for vacancy loss, maintenance, and management expenses. | D31: Multiply | E31: x.75 | F31: x.75 | G31: x.75 | H31: x.75 | I31: x.75 | J31: x.75 | K31: x.75 | L31: x.75 | M31: x.75 | N31: x.75
B32: Equals adjusted monthly rental income. | D32: Total | E32: =E28*0.75 -> 0 | F32: =F28*0.75 -> 0 | G32: =G28*0.75 -> 0 | H32: =H28*0.75 -> 0 | I32: =I28*0.75 -> 0 | J32: =J28*0.75 -> 0 | K32: =K28*0.75 -> 0 | L32: =L28*0.75 -> 0 | ... N32: =N28*0.75 -> 0
A33: B3 | B33: Enter proposed PITIA (for subject property) or existing PITIA (for non-subject property). | D33: Subtract
A34: Step 2B. Result: Monthly qualifying rental income (loss): | D34: Result | E34: =E32-E33 -> 0 | F34: =F32-F33 -> 0 | G34: =G32-G33 -> 0 | H34: =H32-H33 -> 0 | I34: =I32-I33 -> 0 | J34: =J32-J33 -> 0 | K34: =K32-K33 -> 0 | L34: =L32-L33 -> 0 | ... N34: =N32-N33 -> 0
A35: Step 3. Determine the qualifying impact using the result of Step 2A or Step 2B.
A36: If the result of Step 2A or 2B is positive, add the positive amount to the borrower’s monthly qualifying income. Because the PITIA expense was included in the calculations above, do not add it to the debt-to-income (DTI) ratio. | E36: =IF(SUM(E25:N25,E34:N34)>0,SUM(E25:N25,E34:N34),"")
A37: If the result of Step 2A or 2B is negative, include the amount of the loss in the borrower’s monthly expenses when calculating the DTI ratio. | E37: =IF(SUM(E25:N25,E34:N34)<0,SUM(E25:N25,E34:N34),"")
A38: DU Data Entry | C38: Monthly Income and Combined Housing Expenses | E38: Mortgage Liabilities
A39: Subject Property | C39: Enter the amount of the monthly qualifying income (positive result) or monthly qualifying loss (negative result) in “Subject Net Cash.” | E39: For refinance transactions, identify the mortgage as a subject property lien.
A40: Non-Subject Property | C40: Enter the amount of the monthly qualifying income (positive result) or monthly qualifying loss (negative result) in “Net Rental.” | E40: Identify the mortgage as a rental property lien.
A41: Refer to the Rental Income topic in the Selling Guide for additional guidance.

Sheet Back-to-Work
B3: Income Calculations Worksheet
B4: FHA Back to Work Initiative
C7: Borrower: | O7: =IF(#REF!="","",#REF!) -> #REF! | BR7: Loan #: | CE7: =IF(#REF!="","",#REF!) -> #REF!
C10: TOTAL HOUSEHOLD EARNINGS AT TIME OF ECONOMIC EVENT
C11: Actual Date of Economic Event
C12: Borrower's total monthly income at time of economic event | CK12: 0
C13: Other household monthly income at time of economic event | CK13: 0
C14: Total Household Monthly Income at time of economic event | CK14: =SUM(CK12:DA13) -> 0
C17: PERIOD AFTER ECONOMIC EVENT (MINIMUM 6 MONTHS)
C18: Date for the six month period after the date of Economic Event | CK18: =IF(CK11="","",EDATE(CK11,6))
C19: =Data_Income!B948 -> Borrower's total income beginning on 1/1/1900 and ending on 7/1/1900 | CK19: 0
C20: =Data_Income!B949 -> Other household total income beginning on 1/1/1900 and ending on 7/1/1900 | CK20: 0
C21: =Data_Income!B950 -> Grand Total Household Income beginning on 1/1/1900 and ending on 7/1/1900 | CK21: =SUM(CK19:DA20) -> 0
C23: =Data_Income!B951 -> Grand Total Household Monthly Income Average for the period of 1/1/1900 to 7/1/1900 | CK23: =Data_Income!E946 -> 0
C25: Increase / Decrease difference in monthly earnings | CK25: =Data_Income!F946
C28: =Data_Income!B953
C29: =Data_Income!B954
C31: Required Documentation
C32: Loss of Employment
C33: ● | D33: Verify with written VOE to show termination date.
C34: ● | D34: If employer went out of business, then document with copy of borrowers' severance package letter, other publicly available document that the
D35: employer went out of business, and/or receipt of Unemployment income within timeframe.
C36: Loss of Income
C37: ● | D37: Must verify and ensure proper documentation is provided to reflect what the borrower's household income was prior to the Economic Event.
C38: ● | D38: Must verify that either the loss of employment, the loss of income or the loss of both trigerred the Economic Event by documenting the
D39: borrower's household income was after the Economic Event was trigerred.
C40: Satisfactory Credit BEFORE Economic Event
C41: ● | D41: Must verify that borrower(s) had a satisfactory credit history 12 months (minimum) before the Economic Event.
C42: Satisfactory Credit AFTER Economic Event
C43: ● | D43: Must verify no late payments in the last 12 months since the Economic Event.
C44: ● | D44: Borrower's credit history is clear of late housing or installment debt payments and major derogatory credit issues on revolving debts.
C45: ● | D45: Any open mortgage is current and shows a 12 month history of satisfactory payments. Mortgage payments brought current through a loan
D46: modification is acceptable so long as all payments are documented as being paid on time as per the loan modification agreement.
C47: Collections
C48: Regardless of the initial AUS findings, if the total outstanding balance of ALL collections for ALL borrowers is > $2,000, the collections to be paid
C49: off at closing, or provide verification with a letter from the creditor on their letterhead or a credit supplement that borrower has been in a
C50: satisfactory payment plan. Must qualify the borrower with the verified payment amount. If no payment can be verified, qualify the borrower with
C51: each collection account using 5% of the balance as the payment.
C52: Note: Medical collections and charge-offs are excluded from this policy. This policy includes the collection accounts for non-borrowing spouses
C53: who live in a community property state. Collection accounts may NOT be paid down to less than $2,000.
...

Sheet Data_Income
A1: BASIC PARAMETERS
A3: DATES
A5: Today Date | B5: =TODAY() -> 46100
A6: Today Month | B6: =MONTH(TODAY()) -> 3
A7: Today Day | B7: =DAY(B5) -> 19
A8: Year Today | B8: =YEAR(B5) -> 2026
A9: Year to Date | B9: =IF(#REF!="",YEAR(TODAY()),YEAR(#REF!)) -> #REF!
A10: Year Last | B10: =YEAR(TODAY())-1 -> 2025
A11: Year Previous | B11: =YEAR(TODAY())-2 -> 2024
A12: Doc Date | B12: =#REF! -> #REF!
A13: YR Today Beg | B13: =DATE(YEAR(B12),1,1) -> #REF! | C13: YRCB
A14: YR Last Beg | B14: =DATE((YEAR(TODAY())-1),1,1) -> 45658 | C14: YRP1B
A15: YR Last End | B15: =DATE((YEAR(TODAY())-1),12,31) -> 46022 | C15: YRP1E
A16: YR Prev Beg | B16: =DATE((YEAR(TODAY())-2),1,1) -> 45292 | C16: YRP2B
A17: YR Prev End | B17: =DATE((YEAR(TODAY())-2),12,31) -> 45657 | C17: YRP2E
A19: SS & MEDICARE WITHHOLDING CALCULATIONS PARAMETERS
A21: Earnings | B21: Tax % | C21: Withholdings
A22: 0 | B22: 0.062 | C22: =A22*B22 -> 0
B23: 0.0145 | C23: =A22*B23 -> 0
A25: YEAR SELECTIONS \ [ M_YEARS ] \ memory variable list begins with "Select Year" (B27) and ends with "2018" (B32)
A27: ↑ | C27: Select Year
A28: M_YEARS | C28: 2014
A29: | | C29: 2015
A30: | | C30: 2016
A31: | | C31: 2017
A32: ↓ | C32: 2018
A34: DEPRECIATION MILEAGE FACTORS
C36: Year | D36: FNMA Factor
A37: ↑ | C37: 2013 | D37: 0.23
A38: List of FNMA | C38: 2014 | D38: 0.22
A39: Depreciation | C39: 2015 | D39: 0.24
A40: Mileage | C40: 2016 | D40: 0.24
A41: Factors | C41: 2017 | D41: 0.24
A42: ↓ | C42: 2018 | D42: 0.24
A44: INCOME PAY PERIOD FREQUENCY \ [ M_PAYDOCS ] \ memory variable list begins with "Paystub" (C49) and ends with "Other" (C57)
D46: VLOOKUP
B47: Document | C47: Frequency | D47: Search | E47: Pay Periods | F47: Hours | G47: Term
A48: 1
A49: 2 | B49: Paystub | C49: Hourly (H) | D49: Annually (1) | E49: 1 | F49: 2080 | G49: annually
A50: 3 | B50: Written VOE | C50: Weekly (52) | D50: Bi-Weekly (26) | E50: 26 | F50: 80 | G50: bi-weekly
...

Sheet Res Inc Data
A2: Total Loan Amount | B2: =#REF! -> #REF!
A4: W2 - Gross Wages | B4: =#REF! -> #REF!
A5: W2 - Fed Income Tax | B5: =#REF! -> #REF!
A6: W2 - Social Security | B6: =B4*6.2% -> #REF!
A7: W2 - Medicare | B7: =B4*1.45% -> #REF!
A8: W2 - State Inc Tax | B8: =#REF! -> #REF!
A9: W2 - Other Inc Tax | B9: =#REF! -> #REF!
A10: W2 - Total Payroll Ded | B10: =SUM(B5:B9) -> #REF!
A11: W2 - Net Income | B11: =B4-B10 -> #REF!
A13: W2 - Gross Wages | B13: =#REF! -> #REF!
A14: W2 - Fed Income Tax | B14: =#REF! -> #REF!
A15: S/E - Social Security | B15: =B13*12.4% -> #REF!
A16: S/E - Medicare | B16: =B13*2.9% -> #REF!
A17: W2 - State Inc Tax | B17: =#REF! -> #REF!
A18: W2 - Other Inc Tax | B18: =#REF! -> #REF!
A19: S/E - Total Payroll Ded | B19: =SUM(B14:B18) -> #REF!
A20: S/E - Net Income | B20: =B13-B19 -> #REF!
A22: N/T - Gross Wages | B22: =#REF! -> #REF!
A23: N/T - Grossed Up Amt | B23: =#REF! -> #REF!
A24: N/T - Grand Total | B24: =SUM(B22:B23) -> #REF!
A26: PITIA | B26: =#REF! -> #REF!
A27: All Other Payments | B27: =#REF! -> #REF!
A28: Subj Prop Sq Ft | B28: =#REF! -> #REF!
A29: Housing Maintenance | B29: =B28*0.14 -> #REF!
A30: Total All Debts | B30: =B26+B27+B29 -> #REF!
A32: Grand Total Net Inc | B32: =(B11+B20+B22)-B30 -> #REF!
A33: Grand Total All Debt | B33: =#REF! -> #REF!
A35: Active Duty Selection | B35: Select for Veteran Borrowers
B36: Active Duty
B37: Separated from Service
A39: Active Duty Selected | B39: 1
A40: State Selected | B40: 1
A41: State Selected | B41: =VLOOKUP(B40,A67:B118,2) -> ALABAMA
A42: Family Size | B42: =FAMILYSIZE -> #REF!
A43: Active Duty | B43: =IF(B39=2,TRUE,FALSE) -> FALSE
A44: Residual Proposed | B44: =IF(OR(FAMILYSIZE="",FAMILYSIZE=0),0,IF(B2>=80000,VLOOKUP(STATESELECTED,D67:N118,FAMILYSIZE+1),IF(B2<80000,VLOOKUP(STATESELECTED,D129:N180,FAMILYSIZE+1),0))) -> #REF!
A45: Residual Required | B45: =IF(B43=TRUE,B44*95%,B44) -> #REF!
A46: Residual Actual | B46: =B32-B33 -> #REF!
A47: Residual Difference ($) | B47: =RESIDUALACTUAL-RESIDUALREQUIRED -> #REF!
A48: Residual Difference (%) | B48: =IF(B46=0,0,ROUNDDOWN(B47/B44,0)) -> #REF!
...

Sheet MCC Credit
C3: MCC Credit Calculations
AQ6: =PREPAREDBY&" "&VERSIONMSG -> #NAME?
C8: Borrower: | O8: =IF(#REF!="","",#REF!) -> #REF! | BQ8: Loan #: | CC8: =IF(#REF!="","",#REF!) -> #REF!
C12: Original Loan Amount | CH12: 0
C13: Interest Rate | CH13: 0
C14: Total Annual Interest | CH14: =CH12*CH13 -> 0
C15: Annual Tax Credit Percentage | CH15: 0.2
C16: Total Annual Tax Credit | CH16: =CH14*CH15 -> 0
C17: Total Annual Tax Credit Divided by 12 Months for Monthly Credit | CH17: 12
C18: Monthly Tax Credit Benefit for Qualifying Purposes | CH18: =CH16/CH17 -> 0
C22: AVERAGE EARNINGS (PAST 2 YEARS)
C23: Total Earnings (previous 2 years) | CH23: =SUM(AZ17:AZ18) -> 0
C24: Total Months Included in Total Earnings | CH24: =SUM(BQ17:BQ18) -> 0
C25: Average Total Monthly Earnings | CH25: =IF(CH24=0,"",CH23/CH24)
C27: Total Average Earnings for the past 2 years | CH27: =IF(CH25="","",IF(CH25>0,ROUNDDOWN(CH25,0),""))
C31: NOTES
C35: This worksheet is not intended to be legal or comprehensive financial advice. The user assumes any legal liability and responsibility
C36: for the accuracy, completeness, usefulness, effectiveness, reliability, information and/or results obtained from the use of this worksheet.
C37: It is the responsibility of the user to be knowledgeable of the text and data contained in the worksheet, to ensure the accuracy of any
C38: documentation used to complete the worksheet, and that contents are in accordance with product, investor and regulatory requirements.
