Workbook
Name BRANCHOFSERVICE: Data_Income!$C$813:$C$828
Name FAMILYSIZE: #REF!
Name FREQUENCY: Data_Income!$C$48:$C$57
Name M_DOCTYPES: Data_Income!$C$106:$C$115
Name M_PAYDOCS: Data_Income!$B$48:$B$57
Name M_YEARS: Data_Income!$C$27:$C$32
Name RESIDUALACTUAL: 'Res Inc Data'!$B$46
Name RESIDUALDIFF: 'Res Inc Data'!$B$48
Name RESIDUALREQUIRED: 'Res Inc Data'!$B$45
Name STATESELECTED: 'Res Inc Data'!$B$41
Name STATESLIST: 'Res Inc Data'!$D$67:$D$118
Name WVOEHEADINGS: Data_Income!$C$94:$C$102
Name YEARN: Data_Income!$B$8
Name YEARP1: Data_Income!$B$10
Name YEARP2: Data_Income!$B$11
Name YRCB: Data_Income!$B$13
Name YRP1B: Data_Income!$B$14
Name YRP1E: Data_Income!$B$15
Name YRP2B: Data_Income!$B$16
Name YRP2E: Data_Income!$B$17

Sheet 个人rental income(4个以下)
B1: Rental Income Worksheet
B2: Principal Residence, 2- to 4-unit Property: Monthly Qualifying Rental Income
B3: Documentation Required: | F3: Address of Principal Residence:
B4: § Schedule E (IRS Form 1040) OR
B5: § Lease Agreement or Fannie Mae Form 1007 or Form 1025 | E5: Enter | F5: Rental Unit | G5: Rental Unit | H5: Rental Unit
B7: Step 1. When using Schedule E, determine the number of months the property was in service by dividing the Fair Rental Days by 30.
B8: If Fair Rental Days are not reported, the property is considered to be in service for 12 months unless there is evidence of a shorter term of service.
B9: Step 1. Result: The number of months the property was in service: | E9: Result
B10: Step 2. Calculate monthly qualifying rental income using Step 2A: Schedule E OR Step 2B: Lease Agreement or Fannie Mae Form 1025.
B11: Step 2 A. Schedule E - Part I For each property complete ONLY 2A or 2B
B12: A1 | C12: Enter total rents received (from the non-owner-occupied units). May enter rent from individual unit(s) or combine. | E12: Enter
B13: A2 | C13: Subtract total expenses. | E13: Subtract
B14: A3 | C14: Add back insurance expense. | E14: Add
B15: A4 | C15: Add back mortgage interest paid. | E15: Add
B16: A5 | C16: Add back tax expense. | E16: Add
B17: A6 | C17: Add back homeowners’ association dues. This expense must be specifically identified on Schedule E in order to add it back. | E17: Add
B18: A7 | C18: Add back depreciation expense or depletion. | E18: Add
B19: A8 | C19: Add back any one-time extraordinary expense (e.g., casualty loss). There must be evidence of the nature of the one-time extraordinary expense. | E19: Add
C20: Equals adjusted rental income. | E20: Total | F20: =SUM(F12,F14:F19)-F13 -> 0 | G20: =SUM(G12,G14:G19)-G13 -> 0 | H20: =SUM(H12,H14:H19)-H13 -> 0
B21: A9 | C21: Divide by the number of months the property was in service (Step 1 Result). | E21: Divide | F21: =F9 -> 0 | G21: =G9 -> 0 | H21: =H9 -> 0
B22: Step 2A. Result: Monthly qualifying rental income (or loss): | E22: Result | F22: =IF(F21=0,0,F20/F21) -> 0 | G22: =IF(G21=0,0,G20/G21) -> 0 | H22: =IF(H21=0,0,H20/H21) -> 0
B23: Step 2B. Lease Agreement OR Fannie Mae Form 1025 For each property complete ONLY 2A or 2B
B24: This method is used when the transaction is a purchase, the property was acquired subsequent to the most recent tax filing.
B25: B1 | C25: Enter the gross monthly rent (from the lease agreement) or market rent (from Form 1025) for the applicable rental unit | E25: Enter
B28: B2 | C28: Multiply gross monthly rent or market rent by 75% (.75). The remaining 25% accounts for vacancy loss, maintenance, and management expenses. | E28: Multiply | F28: x.75 | G28: x.75 | H28: x.75
C29: Equals monthly rental income per unit | E29: Total | F29: =F25*0.75 -> 0 | G29: =G25*0.75 -> 0 | H29: =H25*0.75 -> 0
B30: B3 | C30: Combine the monthly rental income of all non-owner-occupied rental units (up to a maximum of 3 rental units since rental income is not eligible on the unit occupied by the borrower). | E30: Add | F30: =F22+G22+H22 -> 0
B31: Step 2B. Result: Monthly qualifying rental income: | E31: Result | F31: =F29+G29+H29 -> 0
B32: Step 3. Determine the qualifying impact using the combined result of Step 2A or Step 2B.
B33: 3A | C33: Add the monthly qualifying rental income to the borrower’s monthly qualifying income. | F33: =F22+G22+H22+F31 -> 0
B34: 3B | C34: Identify the full amount of the PITIA as the borrower’s primary housing expense and include it in the debt-to-income ratio. Use proposed PITIA when the subject property; existing PITIA when not the subject property.
B35: DU Data Entry | D35: Monthly Income and Combined Housing Expenses | F35: Mortgage Liabilities
B36: Subject Property | D36: Enter the amount of the monthly qualifying income “Subject Net Cash.” | F36: Include as the borrower’s primary housing expense. For refinance transactions, identify the mortgage as a subject property lien.
B37: Non-Subject Property | D37: Enter the amount of the monthly qualifying income “Net Rental.” | F37: Include as the borrower’s primary housing expense.
B38: Refer to the Rental Income topic in the Selling Guide for additional guidance.

Sheet Back-to-Work
B3: Income Calculations Worksheet
B4: FHA Back to Work Initiative
C7: Borrower: | O7: =IF(#REF!="","",#REF!) -> #REF! | BR7: Loan #: | CE7: =IF(#REF!="","",#REF!) -> #REF!
C10: TOTAL HOUSEHOLD EARNINGS AT TIME OF ECONOMIC EVENT
C11: Actual Date of Economic Event
C12: Borrower's total monthly income at time of economic event | CK12: 0
C13: Other household monthly income at time of economic event | CK13: 0
C14: Total Household Monthly Income at time of economic event | CK14: =SUM(CK12:DA13) -> 0
C17: PERIOD AFTER ECONOMIC EVENT (MINIMUM 6 MONTHS)
C18: Date for the six month period after the date of Economic Event | CK18: =IF(CK11="","",EDATE(CK11,6))
C19: =Data_Income!B948 -> Borrower's total income beginning on 1/1/1900 and ending on 7/1/1900 | CK19: 0
C20: =Data_Income!B949 -> Other household total income beginning on 1/1/1900 and ending on 7/1/1900 | CK20: 0
C21: =Data_Income!B950 -> Grand Total Household Income beginning on 1/1/1900 and ending on 7/1/1900 | CK21: =SUM(CK19:DA20) -> 0
C23: =Data_Income!B951 -> Grand Total Household Monthly Income Average for the period of 1/1/1900 to 7/1/1900 | CK23: =Data_Income!E946 -> 0
C25: Increase / Decrease difference in monthly earnings | CK25: =Data_Income!F946
C28: =Data_Income!B953
C29: =Data_Income!B954
C31: Required Documentation
C32: Loss of Employment
C33: ● | D33: Verify with written VOE to show termination date.
C34: ● | D34: If employer went out of business, then document with copy of borrowers' severance package letter, other publicly available document that the
D35: employer went out of business, and/or receipt of Unemployment income within timeframe.
C36: Loss of Income
C37: ● | D37: Must verify and ensure proper documentation is provided to reflect what the borrower's household income was prior to the Economic Event.
C38: ● | D38: Must verify that either the loss of employment, the loss of income or the loss of both trigerred the Economic Event by documenting the
D39: borrower's household income was after the Economic Event was trigerred.
C40: Satisfactory Credit BEFORE Economic Event
C41: ● | D41: Must verify that borrower(s) had a satisfactory credit history 12 months (minimum) before the Economic Event.
C42: Satisfactory Credit AFTER Economic Event
C43: ● | D43: Must verify no late payments in the last 12 months since the Economic Event.
C44: ● | D44: Borrower's credit history is clear of late housing or installment debt payments and major derogatory credit issues on revolving debts.
C45: ● | D45: Any open mortgage is current and shows a 12 month history of satisfactory payments. Mortgage payments brought current through a loan
D46: modification is acceptable so long as all payments are documented as being paid on time as per the loan modification agreement.
C47: Collections
C48: Regardless of the initial AUS findings, if the total outstanding balance of ALL collections for ALL borrowers is > $2,000, the collections to be paid
C49: off at closing, or provide verification with a letter from the creditor on their letterhead or a credit supplement that borrower has been in a
C50: satisfactory payment plan. Must qualify the borrower with the verified payment amount. If no payment can be verified, qualify the borrower with
C51: each collection account using 5% of the balance as the payment.
C52: Note: Medical collections and charge-offs are excluded from this policy. This policy includes the collection accounts for non-borrowing spouses
C53: who live in a community property state. Collection accounts may NOT be paid down to less than $2,000.
...

Sheet Data_Income
A1: BASIC PARAMETERS
A3: DATES
A5: Today Date | B5: =TODAY() -> 46099
A6: Today Month | B6: =MONTH(TODAY()) -> 3
A7: Today Day | B7: =DAY(B5) -> 18
A8: Year Today | B8: =YEAR(B5) -> 2026
A9: Year to Date | B9: =IF(#REF!="",YEAR(TODAY()),YEAR(#REF!)) -> #REF!
A10: Year Last | B10: =YEAR(TODAY())-1 -> 2025
A11: Year Previous | B11: =YEAR(TODAY())-2 -> 2024
A12: Doc Date | B12: =#REF! -> #REF!
A13: YR Today Beg | B13: =DATE(YEAR(B12),1,1) -> #REF! | C13: YRCB
A14: YR Last Beg | B14: =DATE((YEAR(TODAY())-1),1,1) -> 45658 | C14: YRP1B
A15: YR Last End | B15: =DATE((YEAR(TODAY())-1),12,31) -> 46022 | C15: YRP1E
A16: YR Prev Beg | B16: =DATE((YEAR(TODAY())-2),1,1) -> 45292 | C16: YRP2B
A17: YR Prev End | B17: =DATE((YEAR(TODAY())-2),12,31) -> 45657 | C17: YRP2E
A19: SS & MEDICARE WITHHOLDING CALCULATIONS PARAMETERS
A21: Earnings | B21: Tax % | C21: Withholdings
A22: 0 | B22: 0.062 | C22: =A22*B22 -> 0
B23: 0.0145 | C23: =A22*B23 -> 0
A25: YEAR SELECTIONS \ [ M_YEARS ] \ memory variable list begins with "Select Year" (B27) and ends with "2018" (B32)
A27: ↑ | C27: Select Year
A28: M_YEARS | C28: 2014
A29: | | C29: 2015
A30: | | C30: 2016
A31: | | C31: 2017
A32: ↓ | C32: 2018
A34: DEPRECIATION MILEAGE FACTORS
C36: Year | D36: FNMA Factor
A37: ↑ | C37: 2013 | D37: 0.23
A38: List of FNMA | C38: 2014 | D38: 0.22
A39: Depreciation | C39: 2015 | D39: 0.24
A40: Mileage | C40: 2016 | D40: 0.24
A41: Factors | C41: 2017 | D41: 0.24
A42: ↓ | C42: 2018 | D42: 0.24
A44: INCOME PAY PERIOD FREQUENCY \ [ M_PAYDOCS ] \ memory variable list begins with "Paystub" (C49) and ends with "Other" (C57)
D46: VLOOKUP
B47: Document | C47: Frequency | D47: Search | E47: Pay Periods | F47: Hours | G47: Term
A48: 1
A49: 2 | B49: Paystub | C49: Hourly (H) | D49: Annually (1) | E49: 1 | F49: 2080 | G49: annually
A50: 3 | B50: Written VOE | C50: Weekly (52) | D50: Bi-Weekly (26) | E50: 26 | F50: 80 | G50: bi-weekly
...

Sheet Res Inc Data
A2: Total Loan Amount | B2: =#REF! -> #REF!
A4: W2 - Gross Wages | B4: =#REF! -> #REF!
A5: W2 - Fed Income Tax | B5: =#REF! -> #REF!
A6: W2 - Social Security | B6: =B4*6.2% -> #REF!
A7: W2 - Medicare | B7: =B4*1.45% -> #REF!
A8: W2 - State Inc Tax | B8: =#REF! -> #REF!
A9: W2 - Other Inc Tax | B9: =#REF! -> #REF!
A10: W2 - Total Payroll Ded | B10: =SUM(B5:B9) -> #REF!
A11: W2 - Net Income | B11: =B4-B10 -> #REF!
A13: W2 - Gross Wages | B13: =#REF! -> #REF!
A14: W2 - Fed Income Tax | B14: =#REF! -> #REF!
A15: S/E - Social Security | B15: =B13*12.4% -> #REF!
A16: S/E - Medicare | B16: =B13*2.9% -> #REF!
A17: W2 - State Inc Tax | B17: =#REF! -> #REF!
A18: W2 - Other Inc Tax | B18: =#REF! -> #REF!
A19: S/E - Total Payroll Ded | B19: =SUM(B14:B18) -> #REF!
A20: S/E - Net Income | B20: =B13-B19 -> #REF!
A22: N/T - Gross Wages | B22: =#REF! -> #REF!
A23: N/T - Grossed Up Amt | B23: =#REF! -> #REF!
A24: N/T - Grand Total | B24: =SUM(B22:B23) -> #REF!
A26: PITIA | B26: =#REF! -> #REF!
A27: All Other Payments | B27: =#REF! -> #REF!
A28: Subj Prop Sq Ft | B28: =#REF! -> #REF!
A29: Housing Maintenance | B29: =B28*0.14 -> #REF!
A30: Total All Debts | B30: =B26+B27+B29 -> #REF!
A32: Grand Total Net Inc | B32: =(B11+B20+B22)-B30 -> #REF!
A33: Grand Total All Debt | B33: =#REF! -> #REF!
A35: Active Duty Selection | B35: Select for Veteran Borrowers
B36: Active Duty
B37: Separated from Service
A39: Active Duty Selected | B39: 1
A40: State Selected | B40: 1
A41: State Selected | B41: =VLOOKUP(B40,A67:B118,2) -> ALABAMA
A42: Family Size | B42: =FAMILYSIZE -> #REF!
A43: Active Duty | B43: =IF(B39=2,TRUE(),FALSE()) -> FALSE
A44: Residual Proposed | B44: =IF(OR(FAMILYSIZE="",FAMILYSIZE=0),0,IF(B2>=80000,VLOOKUP(STATESELECTED,D67:N118,FAMILYSIZE+1),IF(B2<80000,VLOOKUP(STATESELECTED,D129:N180,FAMILYSIZE+1),0))) -> #REF!
A45: Residual Required | B45: =IF(B43=TRUE(),B44*95%,B44) -> #REF!
A46: Residual Actual | B46: =B32-B33 -> #REF!
A47: Residual Difference ($) | B47: =RESIDUALACTUAL-RESIDUALREQUIRED -> #REF!
A48: Residual Difference (%) | B48: =IF(B46=0,0,ROUNDDOWN(B47/B44,0)) -> #REF!
...

Sheet MCC Credit
C3: MCC Credit Calculations
AQ6: =preparedby&" "&versionmsg -> #NAME?
C8: Borrower: | O8: =IF(#REF!="","",#REF!) -> #REF! | BQ8: Loan #: | CC8: =IF(#REF!="","",#REF!) -> #REF!
C12: Original Loan Amount | CH12: 0
C13: Interest Rate | CH13: 0
C14: Total Annual Interest | CH14: =CH12*CH13 -> 0
C15: Annual Tax Credit Percentage | CH15: 0.2
C16: Total Annual Tax Credit | CH16: =CH14*CH15 -> 0
C17: Total Annual Tax Credit Divided by 12 Months for Monthly Credit | CH17: 12
C18: Monthly Tax Credit Benefit for Qualifying Purposes | CH18: =CH16/CH17 -> 0
C22: AVERAGE EARNINGS (PAST 2 YEARS)
C23: Total Earnings (previous 2 years) | CH23: =SUM(AZ17:AZ18) -> 0
C24: Total Months Included in Total Earnings | CH24: =SUM(BQ17:BQ18) -> 0
C25: Average Total Monthly Earnings | CH25: =IF(CH24=0,"",CH23/CH24)
C27: Total Average Earnings for the past 2 years | CH27: =IF(CH25="","",IF(CH25>0,ROUNDDOWN(CH25,0),""))
C31: NOTES
C35: This worksheet is not intended to be legal or comprehensive financial advice. The user assumes any legal liability and responsibility
C36: for the accuracy, completeness, usefulness, effectiveness, reliability, information and/or results obtained from the use of this worksheet.
C37: It is the responsibility of the user to be knowledgeable of the text and data contained in the worksheet, to ensure the accuracy of any
C38: documentation used to complete the worksheet, and that contents are in accordance with product, investor and regulatory requirements.
